import { addBug, validateBugRequestData } from "#api/addBug";
import { getStackTrace } from "#plugin/error/modules/getStackTrace";
import { getStore, getUserId } from "#scripts/StoreUtils";

export const handlerFuncForJsUnhandledRejection = async (e: PromiseRejectionEvent): Promise<boolean> => {
  try {
    e.preventDefault();

    /**
     * reason
     * 可能是字符串，比如promise内部reject('string')时
     * 也可能是一个Error对象（含message和stack），比如promise内部throw了new Error('string')时，或者在promise内部reject(new Error('string'))时
     * 建议业务代码里，reject时都reject出一个Error实例，不要直接reject字符串，这样方便拿stack错误栈信息
     */
    const { reason, type } = e;
    const message = reason?.message || reason || "";
    const stack = reason?.stack || getStackTrace() || "";
    const userId = getUserId();
    const { projectId, sdk } = getStore();
    const source = "";

    const requestData: RequestItemAddBug = {
      pi: projectId,
      s: sdk,
      pu: location.href,
      m: message,
      st: stack,
      so: source,
      ty: type,
      u: userId,
      t: Date.now(),
    };

    if (!validateBugRequestData(requestData)) {
      return true;
    }

    addBug(requestData);
    return true;
  } catch (err) {
    // eslint-disable-next-line no-console
    console.log(err);
    return true;
  }
};
